2024-04-14T10:54:52 {"cpu": 0.46728515625, "cpu_total": 4, "cpu_usage": 0.1168212890625, "memory": 2227.0, "memory_total": 24291.0, "memory_usage": 0.09168004610761188, "pipeline_run_id": 86, "pipeline_schedule_id": 4, "pipeline_uuid": "pipeline_manager", "hostname": "10ba7d8502e0", "level": "INFO", "message": "Pipeline pipeline_manager for run 86 in schedule 4 is alive.", "timestamp": 1713092092.814253, "uuid": "a995a0325f654c64b2926b7fe9b7386d"}
2024-04-14T10:54:53 {"cpu": 0.46728515625, "cpu_total": 4, "cpu_usage": 0.1168212890625, "memory": 2269.0, "memory_total": 24291.0, "memory_usage": 0.0934090815528385, "pipeline_run_id": 86, "pipeline_schedule_id": 4, "pipeline_uuid": "pipeline_manager", "hostname": "10ba7d8502e0", "level": "INFO", "message": "Pipeline pipeline_manager for run 86 in schedule 4 is alive.", "timestamp": 1713092093.464547, "uuid": "da3c4b2090744922b949b594d0afe749"}
2024-04-14T10:54:54 {"block_run_id": 332, "block_uuid": "load_bigquery_state", "pipeline_run_id": 86, "pipeline_schedule_id": 4, "pipeline_uuid": "pipeline_manager", "hostname": "10ba7d8502e0", "level": "INFO", "message": "Execute PipelineRun 86, BlockRun 332: pipeline pipeline_manager block load_bigquery_state", "timestamp": 1713092093.99452, "uuid": "5a66650fbfa94648992c86674194671d"}
2024-04-14T10:54:56 {"cpu": 0.486328125, "cpu_total": 4, "cpu_usage": 0.12158203125, "memory": 2240.0, "memory_total": 24291.0, "memory_usage": 0.09221522374542011, "pipeline_run_id": 86, "pipeline_schedule_id": 4, "pipeline_uuid": "pipeline_manager", "hostname": "10ba7d8502e0", "level": "INFO", "message": "Pipeline pipeline_manager for run 86 in schedule 4 is alive.", "timestamp": 1713092096.226351, "uuid": "66782b110b4b419abaf4db0721623f43"}
2024-04-14T10:55:02 {"block_run_id": 332, "block_uuid": "load_bigquery_state", "pipeline_run_id": 86, "pipeline_schedule_id": 4, "pipeline_uuid": "pipeline_manager", "hostname": "10ba7d8502e0", "level": "INFO", "message": "BlockRun 332 (block_uuid: load_bigquery_state) completes.", "timestamp": 1713092102.309393, "uuid": "7bcf029bf2e4406189954571c3c2f134"}
2024-04-14T10:55:04 {"cpu": 0.4892578125, "cpu_total": 4, "cpu_usage": 0.122314453125, "memory": 2233.0, "memory_total": 24291.0, "memory_usage": 0.09192705117121568, "pipeline_run_id": 86, "pipeline_schedule_id": 4, "pipeline_uuid": "pipeline_manager", "hostname": "10ba7d8502e0", "level": "INFO", "message": "Pipeline pipeline_manager for run 86 in schedule 4 is alive.", "timestamp": 1713092104.181379, "uuid": "95432862cdab47f9a04125de6ba00a45"}
2024-04-14T10:55:04 {"block_run_id": 333, "block_uuid": "trigger_pipline", "pipeline_run_id": 86, "pipeline_schedule_id": 4, "pipeline_uuid": "pipeline_manager", "hostname": "10ba7d8502e0", "level": "INFO", "message": "Execute PipelineRun 86, BlockRun 333: pipeline pipeline_manager block trigger_pipline", "timestamp": 1713092104.50942, "uuid": "7ab2fa5f30cc4525aa6984d712060c75"}
2024-04-14T10:55:05 {"block_run_id": 333, "block_uuid": "trigger_pipline", "pipeline_run_id": 86, "pipeline_schedule_id": 4, "pipeline_uuid": "pipeline_manager", "hostname": "10ba7d8502e0", "level": "EXCEPTION", "message": "BlockRun 333 (block_uuid: trigger_pipline) failed.", "timestamp": 1713092105.507941, "uuid": "04003249d4b64c19a8c62e75d248be00", "error": ["Traceback (most recent call last):\n  File \"/usr/local/lib/python3.10/site-packages/mage_ai/data_preparation/models/variable.py\", line 482, in __read_parquet\n    df = self.storage.read_parquet(file_path, engine='pyarrow')\n  File \"/usr/local/lib/python3.10/site-packages/mage_ai/data_preparation/storage/local_storage.py\", line 112, in read_parquet\n    return pd.read_parquet(file_path, engine='pyarrow')\n  File \"/usr/local/lib/python3.10/site-packages/pandas/io/parquet.py\", line 503, in read_parquet\n    return impl.read(\n  File \"/usr/local/lib/python3.10/site-packages/pandas/io/parquet.py\", line 251, in read\n    result = self.api.parquet.read_table(\n  File \"pyarrow/array.pxi\", line 884, in pyarrow.lib._PandasConvertible.to_pandas\n  File \"pyarrow/table.pxi\", line 4192, in pyarrow.lib.Table._to_pandas\n  File \"/usr/local/lib/python3.10/site-packages/pyarrow/pandas_compat.py\", line 766, in table_to_blockmanager\n    ext_columns_dtypes = _get_extension_dtypes(\n  File \"/usr/local/lib/python3.10/site-packages/pyarrow/pandas_compat.py\", line 819, in _get_extension_dtypes\n    pandas_dtype = _pandas_api.pandas_dtype(dtype)\n  File \"pyarrow/pandas-shim.pxi\", line 140, in pyarrow.lib._PandasAPIShim.pandas_dtype\n  File \"pyarrow/pandas-shim.pxi\", line 143, in pyarrow.lib._PandasAPIShim.pandas_dtype\n  File \"/usr/local/lib/python3.10/site-packages/pandas/core/dtypes/common.py\", line 1781, in pandas_dtype\n    npdtype = np.dtype(dtype)\nTypeError: data type 'dbdate' not understood\n\nThe above exception was the direct cause of the following exception:\n\nTraceback (most recent call last):\n  File \"/usr/local/lib/python3.10/site-packages/mage_ai/data_preparation/executors/block_executor.py\", line 613, in execute\n    result = __execute_with_retry()\n  File \"/usr/local/lib/python3.10/site-packages/mage_ai/shared/retry.py\", line 54, in retry_func\n    raise e\n  File \"/usr/local/lib/python3.10/site-packages/mage_ai/shared/retry.py\", line 38, in retry_func\n    return func(*args, **kwargs)\n  File \"/usr/local/lib/python3.10/site-packages/mage_ai/data_preparation/executors/block_executor.py\", line 588, in __execute_with_retry\n    return self._execute(\n  File \"/usr/local/lib/python3.10/site-packages/mage_ai/data_preparation/executors/block_executor.py\", line 1077, in _execute\n    result = self.block.execute_sync(\n  File \"/usr/local/lib/python3.10/site-packages/mage_ai/data_preparation/models/block/__init__.py\", line 1258, in execute_sync\n    raise err\n  File \"/usr/local/lib/python3.10/site-packages/mage_ai/data_preparation/models/block/__init__.py\", line 1167, in execute_sync\n    output = self.execute_block(\n  File \"/usr/local/lib/python3.10/site-packages/mage_ai/data_preparation/models/block/__init__.py\", line 1455, in execute_block\n    self.__get_outputs_from_input_vars(\n  File \"/usr/local/lib/python3.10/site-packages/mage_ai/data_preparation/models/block/__init__.py\", line 1397, in __get_outputs_from_input_vars\n    input_vars, kwargs_vars, upstream_block_uuids = self.fetch_input_variables(\n  File \"/usr/local/lib/python3.10/site-packages/mage_ai/data_preparation/models/block/__init__.py\", line 1769, in fetch_input_variables\n    variables = fetch_input_variables(\n  File \"/usr/local/lib/python3.10/site-packages/mage_ai/data_preparation/models/block/utils.py\", line 545, in fetch_input_variables\n    variable_values = [\n  File \"/usr/local/lib/python3.10/site-packages/mage_ai/data_preparation/models/block/utils.py\", line 546, in <listcomp>\n    pipeline.get_block_variable(\n  File \"/usr/local/lib/python3.10/site-packages/mage_ai/data_preparation/models/pipeline.py\", line 1752, in get_block_variable\n    variable = block.get_variable(\n  File \"/usr/local/lib/python3.10/site-packages/mage_ai/data_preparation/models/block/__init__.py\", line 1860, in get_variable\n    value = variable_manager.get_variable(\n  File \"/usr/local/lib/python3.10/site-packages/mage_ai/data_preparation/variable_manager.py\", line 217, in get_variable\n    return variable.read_data(\n  File \"/usr/local/lib/python3.10/site-packages/mage_ai/data_preparation/models/variable.py\", line 183, in read_data\n    return self.__read_parquet(\n  File \"/usr/local/lib/python3.10/site-packages/mage_ai/data_preparation/models/variable.py\", line 485, in __read_parquet\n    raise Exception(f'Failed to read parquet file: {file_path}') from ex\nException: Failed to read parquet file: /home/src/mage_data/sentistocks/pipelines/pipeline_manager/.variables/4/20240414T000000/load_bigquery_state/output_0/data.parquet\n"], "error_stack": [["  File \"/usr/local/bin/mage\", line 8, in <module>\n    sys.exit(app())\n", "  File \"/usr/local/lib/python3.10/site-packages/typer/main.py\", line 311, in __call__\n    return get_command(self)(*args, **kwargs)\n", "  File \"/usr/local/lib/python3.10/site-packages/click/core.py\", line 1130, in __call__\n    return self.main(*args, **kwargs)\n", "  File \"/usr/local/lib/python3.10/site-packages/typer/core.py\", line 778, in main\n    return _main(\n", "  File \"/usr/local/lib/python3.10/site-packages/typer/core.py\", line 216, in _main\n    rv = self.invoke(ctx)\n", "  File \"/usr/local/lib/python3.10/site-packages/click/core.py\", line 1657, in invoke\n    return _process_result(sub_ctx.command.invoke(sub_ctx))\n", "  File \"/usr/local/lib/python3.10/site-packages/click/core.py\", line 1404, in invoke\n    return ctx.invoke(self.callback, **ctx.params)\n", "  File \"/usr/local/lib/python3.10/site-packages/click/core.py\", line 760, in invoke\n    return __callback(*args, **kwargs)\n", "  File \"/usr/local/lib/python3.10/site-packages/typer/main.py\", line 683, in wrapper\n    return callback(**use_params)  # type: ignore\n", "  File \"/usr/local/lib/python3.10/site-packages/mage_ai/cli/main.py\", line 163, in start\n    start_server(\n", "  File \"/usr/local/lib/python3.10/site-packages/mage_ai/server/server.py\", line 750, in start_server\n    scheduler_manager.start_scheduler()\n", "  File \"/usr/local/lib/python3.10/site-packages/mage_ai/server/scheduler_manager.py\", line 92, in start_scheduler\n    proc.start()\n", "  File \"/usr/local/lib/python3.10/multiprocessing/process.py\", line 121, in start\n    self._popen = self._Popen(self)\n", "  File \"/usr/local/lib/python3.10/multiprocessing/context.py\", line 224, in _Popen\n    return _default_context.get_context().Process._Popen(process_obj)\n", "  File \"/usr/local/lib/python3.10/multiprocessing/context.py\", line 281, in _Popen\n    return Popen(process_obj)\n", "  File \"/usr/local/lib/python3.10/multiprocessing/popen_fork.py\", line 19, in __init__\n    self._launch(process_obj)\n", "  File \"/usr/local/lib/python3.10/multiprocessing/popen_fork.py\", line 71, in _launch\n    code = process_obj._bootstrap(parent_sentinel=child_r)\n", "  File \"/usr/local/lib/python3.10/multiprocessing/process.py\", line 314, in _bootstrap\n    self.run()\n", "  File \"/usr/local/lib/python3.10/multiprocessing/process.py\", line 108, in run\n    self._target(*self._args, **self._kwargs)\n", "  File \"/usr/local/lib/python3.10/site-packages/mage_ai/orchestration/db/process.py\", line 15, in start_session_and_run\n    results = target(*args)\n", "  File \"/usr/local/lib/python3.10/site-packages/mage_ai/server/scheduler_manager.py\", line 53, in run_scheduler\n    LoopTimeTrigger().start()\n", "  File \"/usr/local/lib/python3.10/site-packages/mage_ai/orchestration/triggers/loop_time_trigger.py\", line 14, in start\n    self.run()\n", "  File \"/usr/local/lib/python3.10/site-packages/mage_ai/orchestration/triggers/time_trigger.py\", line 11, in run\n    schedule_all()\n", "  File \"/usr/local/lib/python3.10/site-packages/mage_ai/orchestration/pipeline_scheduler_original.py\", line 1626, in schedule_all\n    PipelineScheduler(r).start()\n", "  File \"/usr/local/lib/python3.10/site-packages/mage_ai/orchestration/db/__init__.py\", line 157, in func_with_rollback\n    return func(*args, **kwargs)\n", "  File \"/usr/local/lib/python3.10/site-packages/mage_ai/orchestration/pipeline_scheduler_original.py\", line 190, in start\n    self.schedule()\n", "  File \"/usr/local/lib/python3.10/site-packages/mage_ai/orchestration/db/__init__.py\", line 157, in func_with_rollback\n    return func(*args, **kwargs)\n", "  File \"/usr/local/lib/python3.10/site-packages/mage_ai/orchestration/pipeline_scheduler_original.py\", line 318, in schedule\n    self.__schedule_blocks(block_runs)\n", "  File \"/usr/local/lib/python3.10/site-packages/mage_ai/orchestration/pipeline_scheduler_original.py\", line 611, in __schedule_blocks\n    job_manager.add_job(\n", "  File \"/usr/local/lib/python3.10/site-packages/mage_ai/orchestration/job_manager.py\", line 28, in add_job\n    self.queue.enqueue(job_id, target, *args, **kwargs)\n", "  File \"/usr/local/lib/python3.10/site-packages/mage_ai/orchestration/queue/process_queue.py\", line 121, in enqueue\n    self.start_worker_pool()\n", "  File \"/usr/local/lib/python3.10/site-packages/mage_ai/orchestration/queue/process_queue.py\", line 198, in start_worker_pool\n    self.worker_pool_proc.start()\n", "  File \"/usr/local/lib/python3.10/multiprocessing/process.py\", line 121, in start\n    self._popen = self._Popen(self)\n", "  File \"/usr/local/lib/python3.10/multiprocessing/context.py\", line 224, in _Popen\n    return _default_context.get_context().Process._Popen(process_obj)\n", "  File \"/usr/local/lib/python3.10/multiprocessing/context.py\", line 281, in _Popen\n    return Popen(process_obj)\n", "  File \"/usr/local/lib/python3.10/multiprocessing/popen_fork.py\", line 19, in __init__\n    self._launch(process_obj)\n", "  File \"/usr/local/lib/python3.10/multiprocessing/popen_fork.py\", line 71, in _launch\n    code = process_obj._bootstrap(parent_sentinel=child_r)\n", "  File \"/usr/local/lib/python3.10/multiprocessing/process.py\", line 314, in _bootstrap\n    self.run()\n", "  File \"/usr/local/lib/python3.10/multiprocessing/process.py\", line 108, in run\n    self._target(*self._args, **self._kwargs)\n", "  File \"/usr/local/lib/python3.10/site-packages/mage_ai/orchestration/queue/process_queue.py\", line 351, in poll_job_and_execute\n    worker.start()\n", "  File \"/usr/local/lib/python3.10/multiprocessing/process.py\", line 121, in start\n    self._popen = self._Popen(self)\n", "  File \"/usr/local/lib/python3.10/multiprocessing/context.py\", line 224, in _Popen\n    return _default_context.get_context().Process._Popen(process_obj)\n", "  File \"/usr/local/lib/python3.10/multiprocessing/context.py\", line 281, in _Popen\n    return Popen(process_obj)\n", "  File \"/usr/local/lib/python3.10/multiprocessing/popen_fork.py\", line 19, in __init__\n    self._launch(process_obj)\n", "  File \"/usr/local/lib/python3.10/multiprocessing/popen_fork.py\", line 71, in _launch\n    code = process_obj._bootstrap(parent_sentinel=child_r)\n", "  File \"/usr/local/lib/python3.10/multiprocessing/process.py\", line 314, in _bootstrap\n    self.run()\n", "  File \"/usr/local/lib/python3.10/site-packages/newrelic/api/background_task.py\", line 117, in wrapper\n    return wrapped(*args, **kwargs)\n", "  File \"/usr/local/lib/python3.10/site-packages/mage_ai/orchestration/queue/process_queue.py\", line 315, in run\n    start_session_and_run(args[1], *args[2], **args[3])\n", "  File \"/usr/local/lib/python3.10/site-packages/mage_ai/orchestration/db/process.py\", line 15, in start_session_and_run\n    results = target(*args)\n", "  File \"/usr/local/lib/python3.10/site-packages/mage_ai/orchestration/pipeline_scheduler_original.py\", line 1163, in run_block\n    return ExecutorFactory.get_block_executor(\n", "  File \"/usr/local/lib/python3.10/site-packages/mage_ai/data_preparation/executors/block_executor.py\", line 641, in execute\n    on_failure(\n", "  File \"/usr/local/lib/python3.10/site-packages/mage_ai/orchestration/db/__init__.py\", line 157, in func_with_rollback\n    return func(*args, **kwargs)\n", "  File \"/usr/local/lib/python3.10/site-packages/mage_ai/orchestration/pipeline_scheduler_original.py\", line 442, in on_block_failure\n    self.logger.exception(\n", "  File \"/usr/local/lib/python3.10/site-packages/mage_ai/data_preparation/logging/logger.py\", line 30, in exception\n    self.__send_message('exception', message, **kwargs)\n", "  File \"/usr/local/lib/python3.10/site-packages/mage_ai/data_preparation/logging/logger.py\", line 65, in __send_message\n    data['error_stack'] = traceback.format_stack(),\n"]], "error_stacktrace": ["Failed to read parquet file: /home/src/mage_data/sentistocks/pipelines/pipeline_manager/.variables/4/20240414T000000/load_bigquery_state/output_0/data.parquet"]}
Traceback (most recent call last):
  File "/usr/local/lib/python3.10/site-packages/mage_ai/data_preparation/models/variable.py", line 482, in __read_parquet
    df = self.storage.read_parquet(file_path, engine='pyarrow')
  File "/usr/local/lib/python3.10/site-packages/mage_ai/data_preparation/storage/local_storage.py", line 112, in read_parquet
    return pd.read_parquet(file_path, engine='pyarrow')
  File "/usr/local/lib/python3.10/site-packages/pandas/io/parquet.py", line 503, in read_parquet
    return impl.read(
  File "/usr/local/lib/python3.10/site-packages/pandas/io/parquet.py", line 251, in read
    result = self.api.parquet.read_table(
  File "pyarrow/array.pxi", line 884, in pyarrow.lib._PandasConvertible.to_pandas
  File "pyarrow/table.pxi", line 4192, in pyarrow.lib.Table._to_pandas
  File "/usr/local/lib/python3.10/site-packages/pyarrow/pandas_compat.py", line 766, in table_to_blockmanager
    ext_columns_dtypes = _get_extension_dtypes(
  File "/usr/local/lib/python3.10/site-packages/pyarrow/pandas_compat.py", line 819, in _get_extension_dtypes
    pandas_dtype = _pandas_api.pandas_dtype(dtype)
  File "pyarrow/pandas-shim.pxi", line 140, in pyarrow.lib._PandasAPIShim.pandas_dtype
  File "pyarrow/pandas-shim.pxi", line 143, in pyarrow.lib._PandasAPIShim.pandas_dtype
  File "/usr/local/lib/python3.10/site-packages/pandas/core/dtypes/common.py", line 1781, in pandas_dtype
    npdtype = np.dtype(dtype)
TypeError: data type 'dbdate' not understood

The above exception was the direct cause of the following exception:

Traceback (most recent call last):
  File "/usr/local/lib/python3.10/site-packages/mage_ai/data_preparation/executors/block_executor.py", line 613, in execute
    result = __execute_with_retry()
  File "/usr/local/lib/python3.10/site-packages/mage_ai/shared/retry.py", line 54, in retry_func
    raise e
  File "/usr/local/lib/python3.10/site-packages/mage_ai/shared/retry.py", line 38, in retry_func
    return func(*args, **kwargs)
  File "/usr/local/lib/python3.10/site-packages/mage_ai/data_preparation/executors/block_executor.py", line 588, in __execute_with_retry
    return self._execute(
  File "/usr/local/lib/python3.10/site-packages/mage_ai/data_preparation/executors/block_executor.py", line 1077, in _execute
    result = self.block.execute_sync(
  File "/usr/local/lib/python3.10/site-packages/mage_ai/data_preparation/models/block/__init__.py", line 1258, in execute_sync
    raise err
  File "/usr/local/lib/python3.10/site-packages/mage_ai/data_preparation/models/block/__init__.py", line 1167, in execute_sync
    output = self.execute_block(
  File "/usr/local/lib/python3.10/site-packages/mage_ai/data_preparation/models/block/__init__.py", line 1455, in execute_block
    self.__get_outputs_from_input_vars(
  File "/usr/local/lib/python3.10/site-packages/mage_ai/data_preparation/models/block/__init__.py", line 1397, in __get_outputs_from_input_vars
    input_vars, kwargs_vars, upstream_block_uuids = self.fetch_input_variables(
  File "/usr/local/lib/python3.10/site-packages/mage_ai/data_preparation/models/block/__init__.py", line 1769, in fetch_input_variables
    variables = fetch_input_variables(
  File "/usr/local/lib/python3.10/site-packages/mage_ai/data_preparation/models/block/utils.py", line 545, in fetch_input_variables
    variable_values = [
  File "/usr/local/lib/python3.10/site-packages/mage_ai/data_preparation/models/block/utils.py", line 546, in <listcomp>
    pipeline.get_block_variable(
  File "/usr/local/lib/python3.10/site-packages/mage_ai/data_preparation/models/pipeline.py", line 1752, in get_block_variable
    variable = block.get_variable(
  File "/usr/local/lib/python3.10/site-packages/mage_ai/data_preparation/models/block/__init__.py", line 1860, in get_variable
    value = variable_manager.get_variable(
  File "/usr/local/lib/python3.10/site-packages/mage_ai/data_preparation/variable_manager.py", line 217, in get_variable
    return variable.read_data(
  File "/usr/local/lib/python3.10/site-packages/mage_ai/data_preparation/models/variable.py", line 183, in read_data
    return self.__read_parquet(
  File "/usr/local/lib/python3.10/site-packages/mage_ai/data_preparation/models/variable.py", line 485, in __read_parquet
    raise Exception(f'Failed to read parquet file: {file_path}') from ex
Exception: Failed to read parquet file: /home/src/mage_data/sentistocks/pipelines/pipeline_manager/.variables/4/20240414T000000/load_bigquery_state/output_0/data.parquet
2024-04-14T10:55:13 {"cpu": 0.5595703125, "cpu_total": 4, "cpu_usage": 0.139892578125, "memory": 2560.0, "memory_total": 24291.0, "memory_usage": 0.10538882713762299, "pipeline_run_id": 86, "pipeline_schedule_id": 4, "pipeline_uuid": "pipeline_manager", "hostname": "10ba7d8502e0", "level": "INFO", "message": "Pipeline pipeline_manager for run 86 in schedule 4 is alive.", "timestamp": 1713092113.836833, "uuid": "bb2676250d8449f5818e2ee20b4136e5"}
