2024-04-13T11:24:35 {"cpu": 0.578125, "cpu_total": 4, "cpu_usage": 0.14453125, "memory": 4893.0, "memory_total": 24291.0, "memory_usage": 0.20143262936890205, "pipeline_run_id": 25, "pipeline_schedule_id": 3, "pipeline_uuid": "coinbase_histo", "hostname": "1c82c87cf97d", "level": "INFO", "message": "Pipeline coinbase_histo for run 25 in schedule 3 is alive.", "timestamp": 1713007475.691436, "uuid": "f23f68f3e6dc477e826a8fe44902f231"}
2024-04-13T11:24:52 {"block_run_id": 97, "block_uuid": "load_coinbase_histodata", "pipeline_run_id": 25, "pipeline_schedule_id": 3, "pipeline_uuid": "coinbase_histo", "hostname": "1c82c87cf97d", "level": "INFO", "message": "Execute PipelineRun 25, BlockRun 97: pipeline coinbase_histo block load_coinbase_histodata", "timestamp": 1713007492.146162, "uuid": "efc7e96e68fa4213820dcc63e6e4b661"}
2024-04-13T11:25:02 {"cpu": 0.7080078125, "cpu_total": 4, "cpu_usage": 0.177001953125, "memory": 4900.0, "memory_total": 24291.0, "memory_usage": 0.2017208019431065, "pipeline_run_id": 25, "pipeline_schedule_id": 3, "pipeline_uuid": "coinbase_histo", "hostname": "1c82c87cf97d", "level": "INFO", "message": "Pipeline coinbase_histo for run 25 in schedule 3 is alive.", "timestamp": 1713007502.514343, "uuid": "100d591b68e04142b6234d6aacc9e5f8"}
2024-04-13T11:25:11 {"block_run_id": 97, "block_uuid": "load_coinbase_histodata", "pipeline_run_id": 25, "pipeline_schedule_id": 3, "pipeline_uuid": "coinbase_histo", "hostname": "1c82c87cf97d", "level": "INFO", "message": "BlockRun 97 (block_uuid: load_coinbase_histodata) completes.", "timestamp": 1713007511.927569, "uuid": "966ed8c7af73436c95eb972ef3c5eac3"}
2024-04-13T11:25:48 {"cpu": 1.205078125, "cpu_total": 4, "cpu_usage": 0.30126953125, "memory": 5039.0, "memory_total": 24291.0, "memory_usage": 0.20744308591659463, "pipeline_run_id": 25, "pipeline_schedule_id": 3, "pipeline_uuid": "coinbase_histo", "hostname": "1c82c87cf97d", "level": "INFO", "message": "Pipeline coinbase_histo for run 25 in schedule 3 is alive.", "timestamp": 1713007548.228979, "uuid": "7c8d3d98941e46838f09342330335910"}
2024-04-13T11:25:50 {"block_run_id": 98, "block_uuid": "fill_na", "pipeline_run_id": 25, "pipeline_schedule_id": 3, "pipeline_uuid": "coinbase_histo", "hostname": "1c82c87cf97d", "level": "INFO", "message": "Execute PipelineRun 25, BlockRun 98: pipeline coinbase_histo block fill_na", "timestamp": 1713007550.916984, "uuid": "6d93a94942e542eaa85f5fa95f8e632b"}
2024-04-13T11:25:57 {"block_run_id": 98, "block_uuid": "fill_na", "pipeline_run_id": 25, "pipeline_schedule_id": 3, "pipeline_uuid": "coinbase_histo", "hostname": "1c82c87cf97d", "level": "INFO", "message": "BlockRun 98 (block_uuid: fill_na) completes.", "timestamp": 1713007557.611169, "uuid": "0a85d563bdbf4c9baca9f1bbab177ef6"}
2024-04-13T11:27:06 {"cpu": 3.1640625, "cpu_total": 4, "cpu_usage": 0.791015625, "memory": 8628.0, "memory_total": 24291.0, "memory_usage": 0.35519328146226997, "pipeline_run_id": 25, "pipeline_schedule_id": 3, "pipeline_uuid": "coinbase_histo", "hostname": "1c82c87cf97d", "level": "INFO", "message": "Pipeline coinbase_histo for run 25 in schedule 3 is alive.", "timestamp": 1713007626.671694, "uuid": "0bd01cc6a4264845bb181294198aae2f"}
2024-04-13T11:28:41 {"block_run_id": 99, "block_uuid": "tranform_histo_datatypes", "pipeline_run_id": 25, "pipeline_schedule_id": 3, "pipeline_uuid": "coinbase_histo", "hostname": "1c82c87cf97d", "level": "INFO", "message": "Execute PipelineRun 25, BlockRun 99: pipeline coinbase_histo block tranform_histo_datatypes", "timestamp": 1713007721.082511, "uuid": "a92959122c5340dcb05109dd465738ca"}
2024-04-13T11:29:35 {"cpu": 9.927734375, "cpu_total": 4, "cpu_usage": 2.48193359375, "memory": 10820.0, "memory_total": 24291.0, "memory_usage": 0.44543246469885966, "pipeline_run_id": 25, "pipeline_schedule_id": 3, "pipeline_uuid": "coinbase_histo", "hostname": "1c82c87cf97d", "level": "INFO", "message": "Pipeline coinbase_histo for run 25 in schedule 3 is alive.", "timestamp": 1713007775.684016, "uuid": "2f4a1dd69f2f43e999c0c066af06c526"}
2024-04-13T11:30:42 {"block_run_id": 99, "block_uuid": "tranform_histo_datatypes", "pipeline_run_id": 25, "pipeline_schedule_id": 3, "pipeline_uuid": "coinbase_histo", "hostname": "1c82c87cf97d", "level": "EXCEPTION", "message": "BlockRun 99 (block_uuid: tranform_histo_datatypes) failed.", "timestamp": 1713007842.777415, "uuid": "8d51cadf09564924bb87004682524561", "error": ["Traceback (most recent call last):\n  File \"/usr/local/lib/python3.10/site-packages/mage_ai/data_preparation/executors/block_executor.py\", line 613, in execute\n    result = __execute_with_retry()\n  File \"/usr/local/lib/python3.10/site-packages/mage_ai/shared/retry.py\", line 54, in retry_func\n    raise e\n  File \"/usr/local/lib/python3.10/site-packages/mage_ai/shared/retry.py\", line 38, in retry_func\n    return func(*args, **kwargs)\n  File \"/usr/local/lib/python3.10/site-packages/mage_ai/data_preparation/executors/block_executor.py\", line 588, in __execute_with_retry\n    return self._execute(\n  File \"/usr/local/lib/python3.10/site-packages/mage_ai/data_preparation/executors/block_executor.py\", line 1077, in _execute\n    result = self.block.execute_sync(\n  File \"/usr/local/lib/python3.10/site-packages/mage_ai/data_preparation/models/block/__init__.py\", line 1258, in execute_sync\n    raise err\n  File \"/usr/local/lib/python3.10/site-packages/mage_ai/data_preparation/models/block/__init__.py\", line 1167, in execute_sync\n    output = self.execute_block(\n  File \"/usr/local/lib/python3.10/site-packages/mage_ai/data_preparation/models/block/__init__.py\", line 1473, in execute_block\n    outputs = self._execute_block(\n  File \"/usr/local/lib/python3.10/site-packages/mage_ai/data_preparation/models/block/__init__.py\", line 1629, in _execute_block\n    outputs = self.execute_block_function(\n  File \"/usr/local/lib/python3.10/site-packages/mage_ai/data_preparation/models/block/__init__.py\", line 1668, in execute_block_function\n    output = block_function_updated(*input_vars, **global_vars)\n  File \"<string>\", line 42, in transform\n  File \"<string>\", line 33, in transform\n  File \"/usr/local/lib/python3.10/site-packages/pyspark/sql/session.py\", line 497, in getOrCreate\n    sc = SparkContext.getOrCreate(sparkConf)\n  File \"/usr/local/lib/python3.10/site-packages/pyspark/context.py\", line 515, in getOrCreate\n    SparkContext(conf=conf or SparkConf())\n  File \"/usr/local/lib/python3.10/site-packages/pyspark/context.py\", line 203, in __init__\n    self._do_init(\n  File \"/usr/local/lib/python3.10/site-packages/pyspark/context.py\", line 296, in _do_init\n    self._jsc = jsc or self._initialize_context(self._conf._jconf)\n  File \"/usr/local/lib/python3.10/site-packages/pyspark/context.py\", line 421, in _initialize_context\n    return self._jvm.JavaSparkContext(jconf)\n  File \"/usr/local/lib/python3.10/site-packages/py4j/java_gateway.py\", line 1587, in __call__\n    return_value = get_return_value(\n  File \"/usr/local/lib/python3.10/site-packages/py4j/protocol.py\", line 334, in get_return_value\n    raise Py4JError(\npy4j.protocol.Py4JError: An error occurred while calling None.org.apache.spark.api.java.JavaSparkContext\n"], "error_stack": [["  File \"/usr/local/bin/mage\", line 8, in <module>\n    sys.exit(app())\n", "  File \"/usr/local/lib/python3.10/site-packages/typer/main.py\", line 311, in __call__\n    return get_command(self)(*args, **kwargs)\n", "  File \"/usr/local/lib/python3.10/site-packages/click/core.py\", line 1130, in __call__\n    return self.main(*args, **kwargs)\n", "  File \"/usr/local/lib/python3.10/site-packages/typer/core.py\", line 778, in main\n    return _main(\n", "  File \"/usr/local/lib/python3.10/site-packages/typer/core.py\", line 216, in _main\n    rv = self.invoke(ctx)\n", "  File \"/usr/local/lib/python3.10/site-packages/click/core.py\", line 1657, in invoke\n    return _process_result(sub_ctx.command.invoke(sub_ctx))\n", "  File \"/usr/local/lib/python3.10/site-packages/click/core.py\", line 1404, in invoke\n    return ctx.invoke(self.callback, **ctx.params)\n", "  File \"/usr/local/lib/python3.10/site-packages/click/core.py\", line 760, in invoke\n    return __callback(*args, **kwargs)\n", "  File \"/usr/local/lib/python3.10/site-packages/typer/main.py\", line 683, in wrapper\n    return callback(**use_params)  # type: ignore\n", "  File \"/usr/local/lib/python3.10/site-packages/mage_ai/cli/main.py\", line 163, in start\n    start_server(\n", "  File \"/usr/local/lib/python3.10/site-packages/mage_ai/server/server.py\", line 745, in start_server\n    scheduler_manager.start_scheduler()\n", "  File \"/usr/local/lib/python3.10/site-packages/mage_ai/server/scheduler_manager.py\", line 92, in start_scheduler\n    proc.start()\n", "  File \"/usr/local/lib/python3.10/multiprocessing/process.py\", line 121, in start\n    self._popen = self._Popen(self)\n", "  File \"/usr/local/lib/python3.10/multiprocessing/context.py\", line 224, in _Popen\n    return _default_context.get_context().Process._Popen(process_obj)\n", "  File \"/usr/local/lib/python3.10/multiprocessing/context.py\", line 281, in _Popen\n    return Popen(process_obj)\n", "  File \"/usr/local/lib/python3.10/multiprocessing/popen_fork.py\", line 19, in __init__\n    self._launch(process_obj)\n", "  File \"/usr/local/lib/python3.10/multiprocessing/popen_fork.py\", line 71, in _launch\n    code = process_obj._bootstrap(parent_sentinel=child_r)\n", "  File \"/usr/local/lib/python3.10/multiprocessing/process.py\", line 314, in _bootstrap\n    self.run()\n", "  File \"/usr/local/lib/python3.10/multiprocessing/process.py\", line 108, in run\n    self._target(*self._args, **self._kwargs)\n", "  File \"/usr/local/lib/python3.10/site-packages/mage_ai/orchestration/db/process.py\", line 15, in start_session_and_run\n    results = target(*args)\n", "  File \"/usr/local/lib/python3.10/site-packages/mage_ai/server/scheduler_manager.py\", line 53, in run_scheduler\n    LoopTimeTrigger().start()\n", "  File \"/usr/local/lib/python3.10/site-packages/mage_ai/orchestration/triggers/loop_time_trigger.py\", line 14, in start\n    self.run()\n", "  File \"/usr/local/lib/python3.10/site-packages/mage_ai/orchestration/triggers/time_trigger.py\", line 11, in run\n    schedule_all()\n", "  File \"/usr/local/lib/python3.10/site-packages/mage_ai/orchestration/pipeline_scheduler_original.py\", line 1624, in schedule_all\n    PipelineScheduler(r).start()\n", "  File \"/usr/local/lib/python3.10/site-packages/mage_ai/orchestration/db/__init__.py\", line 157, in func_with_rollback\n    return func(*args, **kwargs)\n", "  File \"/usr/local/lib/python3.10/site-packages/mage_ai/orchestration/pipeline_scheduler_original.py\", line 190, in start\n    self.schedule()\n", "  File \"/usr/local/lib/python3.10/site-packages/mage_ai/orchestration/db/__init__.py\", line 157, in func_with_rollback\n    return func(*args, **kwargs)\n", "  File \"/usr/local/lib/python3.10/site-packages/mage_ai/orchestration/pipeline_scheduler_original.py\", line 318, in schedule\n    self.__schedule_blocks(block_runs)\n", "  File \"/usr/local/lib/python3.10/site-packages/mage_ai/orchestration/pipeline_scheduler_original.py\", line 611, in __schedule_blocks\n    job_manager.add_job(\n", "  File \"/usr/local/lib/python3.10/site-packages/mage_ai/orchestration/job_manager.py\", line 28, in add_job\n    self.queue.enqueue(job_id, target, *args, **kwargs)\n", "  File \"/usr/local/lib/python3.10/site-packages/mage_ai/orchestration/queue/process_queue.py\", line 121, in enqueue\n    self.start_worker_pool()\n", "  File \"/usr/local/lib/python3.10/site-packages/mage_ai/orchestration/queue/process_queue.py\", line 198, in start_worker_pool\n    self.worker_pool_proc.start()\n", "  File \"/usr/local/lib/python3.10/multiprocessing/process.py\", line 121, in start\n    self._popen = self._Popen(self)\n", "  File \"/usr/local/lib/python3.10/multiprocessing/context.py\", line 224, in _Popen\n    return _default_context.get_context().Process._Popen(process_obj)\n", "  File \"/usr/local/lib/python3.10/multiprocessing/context.py\", line 281, in _Popen\n    return Popen(process_obj)\n", "  File \"/usr/local/lib/python3.10/multiprocessing/popen_fork.py\", line 19, in __init__\n    self._launch(process_obj)\n", "  File \"/usr/local/lib/python3.10/multiprocessing/popen_fork.py\", line 71, in _launch\n    code = process_obj._bootstrap(parent_sentinel=child_r)\n", "  File \"/usr/local/lib/python3.10/multiprocessing/process.py\", line 314, in _bootstrap\n    self.run()\n", "  File \"/usr/local/lib/python3.10/multiprocessing/process.py\", line 108, in run\n    self._target(*self._args, **self._kwargs)\n", "  File \"/usr/local/lib/python3.10/site-packages/mage_ai/orchestration/queue/process_queue.py\", line 351, in poll_job_and_execute\n    worker.start()\n", "  File \"/usr/local/lib/python3.10/multiprocessing/process.py\", line 121, in start\n    self._popen = self._Popen(self)\n", "  File \"/usr/local/lib/python3.10/multiprocessing/context.py\", line 224, in _Popen\n    return _default_context.get_context().Process._Popen(process_obj)\n", "  File \"/usr/local/lib/python3.10/multiprocessing/context.py\", line 281, in _Popen\n    return Popen(process_obj)\n", "  File \"/usr/local/lib/python3.10/multiprocessing/popen_fork.py\", line 19, in __init__\n    self._launch(process_obj)\n", "  File \"/usr/local/lib/python3.10/multiprocessing/popen_fork.py\", line 71, in _launch\n    code = process_obj._bootstrap(parent_sentinel=child_r)\n", "  File \"/usr/local/lib/python3.10/multiprocessing/process.py\", line 314, in _bootstrap\n    self.run()\n", "  File \"/usr/local/lib/python3.10/site-packages/newrelic/api/background_task.py\", line 117, in wrapper\n    return wrapped(*args, **kwargs)\n", "  File \"/usr/local/lib/python3.10/site-packages/mage_ai/orchestration/queue/process_queue.py\", line 315, in run\n    start_session_and_run(args[1], *args[2], **args[3])\n", "  File \"/usr/local/lib/python3.10/site-packages/mage_ai/orchestration/db/process.py\", line 15, in start_session_and_run\n    results = target(*args)\n", "  File \"/usr/local/lib/python3.10/site-packages/mage_ai/orchestration/pipeline_scheduler_original.py\", line 1161, in run_block\n    return ExecutorFactory.get_block_executor(\n", "  File \"/usr/local/lib/python3.10/site-packages/mage_ai/data_preparation/executors/block_executor.py\", line 641, in execute\n    on_failure(\n", "  File \"/usr/local/lib/python3.10/site-packages/mage_ai/orchestration/db/__init__.py\", line 157, in func_with_rollback\n    return func(*args, **kwargs)\n", "  File \"/usr/local/lib/python3.10/site-packages/mage_ai/orchestration/pipeline_scheduler_original.py\", line 442, in on_block_failure\n    self.logger.exception(\n", "  File \"/usr/local/lib/python3.10/site-packages/mage_ai/data_preparation/logging/logger.py\", line 30, in exception\n    self.__send_message('exception', message, **kwargs)\n", "  File \"/usr/local/lib/python3.10/site-packages/mage_ai/data_preparation/logging/logger.py\", line 65, in __send_message\n    data['error_stack'] = traceback.format_stack(),\n"]], "error_stacktrace": ["An error occurred while calling None.org.apache.spark.api.java.JavaSparkContext"]}
Traceback (most recent call last):
  File "/usr/local/lib/python3.10/site-packages/mage_ai/data_preparation/executors/block_executor.py", line 613, in execute
    result = __execute_with_retry()
  File "/usr/local/lib/python3.10/site-packages/mage_ai/shared/retry.py", line 54, in retry_func
    raise e
  File "/usr/local/lib/python3.10/site-packages/mage_ai/shared/retry.py", line 38, in retry_func
    return func(*args, **kwargs)
  File "/usr/local/lib/python3.10/site-packages/mage_ai/data_preparation/executors/block_executor.py", line 588, in __execute_with_retry
    return self._execute(
  File "/usr/local/lib/python3.10/site-packages/mage_ai/data_preparation/executors/block_executor.py", line 1077, in _execute
    result = self.block.execute_sync(
  File "/usr/local/lib/python3.10/site-packages/mage_ai/data_preparation/models/block/__init__.py", line 1258, in execute_sync
    raise err
  File "/usr/local/lib/python3.10/site-packages/mage_ai/data_preparation/models/block/__init__.py", line 1167, in execute_sync
    output = self.execute_block(
  File "/usr/local/lib/python3.10/site-packages/mage_ai/data_preparation/models/block/__init__.py", line 1473, in execute_block
    outputs = self._execute_block(
  File "/usr/local/lib/python3.10/site-packages/mage_ai/data_preparation/models/block/__init__.py", line 1629, in _execute_block
    outputs = self.execute_block_function(
  File "/usr/local/lib/python3.10/site-packages/mage_ai/data_preparation/models/block/__init__.py", line 1668, in execute_block_function
    output = block_function_updated(*input_vars, **global_vars)
  File "<string>", line 42, in transform
  File "<string>", line 33, in transform
  File "/usr/local/lib/python3.10/site-packages/pyspark/sql/session.py", line 497, in getOrCreate
    sc = SparkContext.getOrCreate(sparkConf)
  File "/usr/local/lib/python3.10/site-packages/pyspark/context.py", line 515, in getOrCreate
    SparkContext(conf=conf or SparkConf())
  File "/usr/local/lib/python3.10/site-packages/pyspark/context.py", line 203, in __init__
    self._do_init(
  File "/usr/local/lib/python3.10/site-packages/pyspark/context.py", line 296, in _do_init
    self._jsc = jsc or self._initialize_context(self._conf._jconf)
  File "/usr/local/lib/python3.10/site-packages/pyspark/context.py", line 421, in _initialize_context
    return self._jvm.JavaSparkContext(jconf)
  File "/usr/local/lib/python3.10/site-packages/py4j/java_gateway.py", line 1587, in __call__
    return_value = get_return_value(
  File "/usr/local/lib/python3.10/site-packages/py4j/protocol.py", line 334, in get_return_value
    raise Py4JError(
py4j.protocol.Py4JError: An error occurred while calling None.org.apache.spark.api.java.JavaSparkContext
